Workbook

Sheet 1. Resumo Executivo
A1: IMPULSO — PLANO DE NEGÓCIOS COMPLETO
B2: Agência boutique de implementação de e-commerce e sites institucionais — análise da banca de especialistas
A4: IDENTIDADE DA EMPRESA
B5: Nome da empresa | C5: Impulso
B6: Posicionamento | C6: Implementação rápida e profissional de lojas virtuais e sites institucionais para PMEs e empreendedores digitais
B7: Público-alvo (ICP) | C7: PMEs físicas migrando para digital (Carla); empreendedores DTC em validação (Rodrigo); B2B PME catálogo digital (Mariana)
B8: Proposta de valor | C8: "Sua loja online profissional no ar em 48 horas — pronta para vender — com método, suporte e crescimento contínuo, sem freelancer sumido nem agência que demora 3 meses."
B9: Diferenciais | C9: Método Impulso 48h proprietário (checklist + biblioteca de blocos + integrações pré-configuradas + kit IA); especialização vertical; conversão projeto→recorrência
B10: Serviços | C10: 1) Projeto 48 Horas (Start/Pro/Premium) | 2) Projetos personalizados | 3) Planos mensais de suporte (Essencial/Pro/Growth) | 4) Receita de parceria com plataformas (20% MRR) | 5) Gestão de tráfego pago
B11: Modelo de receita | C11: Mix transacional (projetos) + recorrente (suporte + parceria + gestão). Meta 24 meses: 50% receita recorrente
B12: Regime tributário | C12: Simples Nacional, Anexo III com Fator R ≥ 28% (pró-labore é a alavanca). Premissa de 12% é conservadora — efetivo real é 6-8,4% até R$ 30k/mês
B13: Operação | C13: Home office, 2 sócios sêniors, capacidade combinada ~180h/mês de execução pura
A15: PRINCIPAIS PREMISSAS
B16: Premissa | C16: Valor | D16: Origem
B17: Número de sócios operacionais | C17: ='2. Premissas'!C5 | E17: Definido pelo usuário
B18: Pró-labore por sócio (mensal) | C18: ='2. Premissas'!C7 | E18: Definido pelo usuário
B19: Pró-labore total mensal | C19: ='2. Premissas'!C9 | E19: =2 sócios × R$ 4.000
B20: Pró-labore anual total | C20: ='2. Premissas'!C10 | E20: =mensal × 12
B21: Horas produtivas mensais (2 sócios) | C21: ='2. Premissas'!C19 | E21: Análise operacional
B22: Custo/hora interno (R$) | C22: ='2. Premissas'!C68 | E22: =(CF total) / horas produtivas
B23: Margem recomendada | C23: ='2. Premissas'!C27 | E23: Editável
B24: Imposto Simples efetivo (premissa) | C24: ='2. Premissas'!C31 | E24: Editável — confer. Anexo III
B25: Reserva de capital de giro recomendada | C25: ='2. Premissas'!C65 | E25: 6× burn (recomendação CFO)
A27: INDICADORES-CHAVE DOS 3 CENÁRIOS (linkados à aba 12)
B28: Indicador | C28: Pessimista | D28: Realista | E28: Otimista | F28: Como é calculado
B29: Receita bruta anual | C29: ='12. Cenários'!P11 | D29: ='12. Cenários'!P38 | E29: ='12. Cenários'!P65 | F29: Soma 12 meses de cada cenário
B30: Receita média mensal | C30: ='12. Cenários'!P11/12 | D30: ='12. Cenários'!P38/12 | E30: ='12. Cenários'!P65/12 | F30: Anual ÷ 12
B31: Lucro líquido anual | C31: ='12. Cenários'!P17 | D31: ='12. Cenários'!P44 | E31: ='12. Cenários'!P71 | F31: Soma do lucro líquido 12m
B32: Margem líquida média | C32: ='12. Cenários'!P18 | D32: ='12. Cenários'!P45 | E32: ='12. Cenários'!P72 | F32: Lucro anual ÷ Receita anual
B33: Caixa acumulado mês 12 | C33: ='12. Cenários'!O19 | D33: ='12. Cenários'!O46 | E33: ='12. Cenários'!O73 | F33: Caixa final do mês 12
B34: Ponto de equilíbrio mensal | C34: ='15. Ponto Equilíbrio'!C12 | D34: ='15. Ponto Equilíbrio'!C12 | E34: ='15. Ponto Equilíbrio'!C12 | F34: CF ÷ (1 − deduções variáveis)
B35: Pró-labore total mensal | C35: ='2. Premissas'!C9 | D35: ='2. Premissas'!C9 | E35: ='2. Premissas'!C9 | F35: Premissa editável
B36: Custos fixos mensais (sem pró-labore) | C36: ='2. Premissas'!C62 | D36: ='2. Premissas'!C62 | E36: ='2. Premissas'!C62 | F36: Soma fixos da aba 2
B37: Payback estimado | C37: Inviável s/ aporte | D37: ~9 meses (caixa+ no mês 6) | E37: ~4 meses | F37: Análise CFO
A39: CONCLUSÃO EXECUTIVA DO SQUAD
B40: 🟢 VIÁVEL no Realista (margem líquida ~24%, payback ~9m) e robusto no Otimista (margem 44%). 🔴 Pessimista é inviável sem aporte ou ajuste de pró-labore. Os 3 AJUSTES NÃO-NEGOCIÁVEIS identificados pelo squad: 1) Pró-labore ESCALONADO — começar com R$ 3k/sócio (mês 1-3) → R$ 3,5k (4-6) → R$ 4k (7+) quando MRR > R$ 10k. Sustenta o Fator R do Anexo III (28%) e protege o caixa. 2) Escopo do 48h TAXATIVO — máximo 20 SKUs, 1 gateway, 1 frete, 4 páginas, plataformas Shopify/Nuvemshop/Tray. Woo fora do 48h. Sem isso, vira processo no PROCON (art. 30, 37 CDC). 3) Foco comercial em MRR — meta de 50% de receita recorrente até 24 meses. Cada R$ 1 de MRR vale 3-5× R$ 1 de projeto. ⚠️ RISCO ESTRATÉGICO MAIOR (24-36 meses): comoditização do setup básico por IA generativa (Shopify Magic, Wix ADI). A tese precisa migrar de 'implementador' para 'operador de crescimento de PMEs digitais' — vender resultado de vendas, não apenas loja no ar. ✅ AÇÕES OBRIGATÓRIAS antes da 1ª venda: constituir LTDA + CNAEs corretos + Simples; contrato dual-track (B2B/B2C); Política do Projeto 48 Horas com aceite eletrônico; LGPD (DPA); registrar marca no INPI; reserva de R$ 50k de capital de giro.

Sheet 2. Premissas
A1: PREMISSAS GERAIS — EDITE AQUI E TODA A PLANILHA SE ATUALIZA
B2: Células em AMARELO são premissas editáveis. Verde = fórmulas (não editar). Cinza = referência. | E2: REFERÊNCIAS-CHAVE: C9=Pró-labore total | C19=Horas produtivas | C62=Custos fixos s/PL | C63=CF total | C68=Custo/h | C70=Deduções var | C31=Imposto
A4: SÓCIOS E PRÓ-LABORE
B5: Número de sócios operacionais | C5: 2 | D5: un | E5: Definição da operação
B7: Pró-labore mensal por sócio (R$) | C7: 4000 | D7: R$/mês | E7: Premissa do usuário — R$ 4.000/sócio
B8: INSS sócio (11% sobre pró-labore individual) | C8: =C7*0.11 | D8: R$/mês | E8: Art. 21 Lei 8.212/91 (até teto)
B9: Pró-labore TOTAL mensal | C9: =C7*C5 | D9: R$/mês | E9: Fórmula = pró-labore × sócios
B10: Pró-labore TOTAL anual | C10: =C9*12 | D10: R$/ano | E10: Fórmula = mensal × 12
B11: INSS sócios TOTAL mensal | C11: =C8*C5 | D11: R$/mês | E11: Soma do INSS dos sócios
A13: CAPACIDADE OPERACIONAL
B14: Dias úteis por mês | C14: 22 | D14: dias | E14: Premissa padrão BR
B15: Horas/dia por sócio | C15: 8 | D15: h | E15: Jornada
B16: Horas BRUTAS mensais por sócio | C16: =C14*C15 | D16: h | E16: Fórmula = dias × horas/dia
B17: Horas brutas mensais TOTAIS (2 sócios) | C17: =C16*C5 | D17: h | E17: Fórmula = horas/sócio × sócios
B18: % de horas produtivas reais (descontado comercial, admin, atendimento) | C18: 0.5 | D18: % | E18: Análise operacional: ~50% (vendas 15% + atendimento 10% + pós-venda 10% + admin 8% + gestão 7%)
B19: Horas PRODUTIVAS mensais (execução pura) | C19: =C17*C18 | D19: h | E19: Fórmula. Padrão de planejamento: 176h
B20: Ganho médio de produtividade com IA (%) | C20: 0.25 | D20: % | E20: Análise operacional — ganho real médio (não 80%+ ilusório)
B21: Capacidade-alvo (% de utilização sustentável) | C21: 0.8 | D21: % | E21: Operar ≤80% para evitar burnout
B22: Horas FATURÁVEIS mensais (alvo) | C22: =C19*C21 | D22: h | E22: Horas produtivas × utilização alvo
A24: PRECIFICAÇÃO E MARGEM
B25: Valor/hora desejado (referência mercado) | C25: 250 | D25: R$/h | E25: Mercado: freela sênior R$ 150-400/h; agência R$ 200-600/h
B26: Margem MÍNIMA aceitável | C26: 0.2 | D26: % | E26: Piso para não vender no prejuízo
B27: Margem RECOMENDADA | C27: 0.4 | D27: % | E27: Saudável para serviços
B28: Margem PREMIUM (sem desconto) | C28: 0.55 | D28: % | E28: Preço de ancoragem
A30: IMPOSTOS E TAXAS DE PAGAMENTO
B31: Imposto Simples efetivo (premissa do projeto) | C31: 0.12 | D31: % | E31: Premissa do usuário. Real: 6% até R$ 180k; 8,4% até R$ 360k; 11% até R$ 720k (Anexo III)
B32: Taxa PIX (gateway) | C32: 0.005 | D32: % | E32: InfinitePay 0%; PagBank até 1,89%
B33: Taxa cartão à vista | C33: 0.035 | D33: % | E33: Stone 3,11%; PagBank D+30 3,19%; InfinitePay 2,69%
B34: Taxa cartão 3x | C34: 0.045 | D34: % | E34: Stone parcelado start 5,41%; média 4-5%
B35: Taxa cartão 6x | C35: 0.065 | D35: % | E35: Faixa intermediária
B36: Taxa cartão 10x | C36: 0.095 | D36: % | E36: Mercado Pago D+1 ~12,49%; InfinitePay 12x 8,99%
B37: Taxa cartão 12x | C37: 0.115 | D37: % | E37: Faixa iniciante MP até 22%; recomenda-se repassar juros >6x
B38: Inadimplência projetada (PCLD) | C38: 0.04 | D38: % | E38: B2B serviços BR — 4% conservador. Serasa: 55,2% inadimplência em serviços
A40: CUSTOS FIXOS MENSAIS (sem pró-labore)
B41: Internet empresarial (fibra 200-500 Mbps, 2 sócios) | C41: 200 | D41: R$/mês | E41: Vivo R$ 128,98; TIM R$ 119,99; média BR R$ 100-180
B42: Energia adicional home office (2 sócios) | C42: 80 | D42: R$/mês | E42: Enel SP R$ 0,91/kWh × ~45 kWh/sócio (R$ 40/sócio)
B43: Google Workspace Business Starter (2 usuários) | C43: 65 | D43: R$/mês | E43: R$ 32,72/user × 2 (anual)
B44: Ferramentas IA (ChatGPT Plus + Claude Pro) | C44: 220 | D44: R$/mês | E44: US$ 20 × 2 ≈ R$ 108 × 2
B45: Figma Professional (2 editores anual) | C45: 162 | D45: R$/mês | E45: US$ 15/editor × 2 ≈ R$ 81 × 2
B46: Canva Pro Teams | C46: 39 | D46: R$/mês | E46: R$ 470/ano = R$ 39/mês
...

Sheet 3. Pesquisa Mercado
A1: PESQUISA DE MERCADO E REFERÊNCIAS REAIS
B2: Dados consultados em 2026-06-10 — câmbio referência USD ≈ R$ 5,42 | EUR ≈ R$ 5,90
A4: A. PLATAFORMAS DE E-COMMERCE (preço mensal BRL e programas de parceria)
B5: Item | C5: Mínimo | D5: Médio | E5: Máximo | F5: Data | G5: Fonte / Observação
B6: Shopify Basic (US$ 39 anual US$ 29) | C6: 157 | D6: 211 | E6: 211 | F6: 2026-06-10 | G6: shopify.com/pricing — IOF 6,38%
B7: Shopify Grow (US$ 105 anual US$ 79) | C7: 428 | D7: 569 | E7: 569 | F7: 2026-06-10 | G7: shopify.com/pricing
B8: Shopify Advanced (US$ 399 anual US$ 299) | C8: 1621 | D8: 2163 | E8: 2163 | F8: 2026-06-10 | G8: shopify.com/pricing
B9: Shopify Partners — comissão recorrente | D9: 20% | F9: 2026-06-10 | G9: help.shopify.com/en/partners/partner-program/how-to-earn
B10: Tray — faixa de planos | C10: 19 | D10: 99 | E10: 449 | F10: 2026-06-10 | G10: tray.com.br/planos-precos
B11: Tray Partners — comissão recorrente | D11: 20-30% | F11: 2026-06-10 | G11: tray.com.br/partners
B12: Nuvemshop Essencial | C12: 59 | D12: 59 | E12: 59 | F12: 2026-06-10 | G12: nuvemshop.com.br/planos-e-precos
B13: Nuvemshop Impulso (plano homônimo) | C13: 139 | D13: 139 | E13: 139 | F13: 2026-06-10 | G13: nuvemshop.com.br/planos-e-precos
B14: Nuvemshop Escala | C14: 389 | D14: 389 | E14: 389 | F14: 2026-06-10 | G14: nuvemshop.com.br/planos-e-precos
B15: Nuvemshop Experts — comissão | D15: 20% | F15: 2026-06-10 | G15: atendimento.nuvemshop.com.br — comissões vigentes
B16: WooCommerce hospedagem entry (Hostinger/KingHost) | C16: 13 | D16: 30 | E16: 50 | F16: 2026-06-10 | G16: hostinger.com/br/tutoriais/wordpress-preco; site.king.host
B17: WooCommerce TCO total (hosp+plugins) | C17: 100 | D17: 250 | E17: 500 | F17: 2026-06-10 | G17: Composição — estimativa de mercado
B18: Wix Core eCommerce (US$ 29) | C18: 157 | D18: 157 | E18: 157 | F18: 2026-06-10 | G18: tooltester.com/wix
B19: BigCommerce Core (US$ 39, cap US$ 50k/ano) | C19: 211 | D19: 211 | E19: 211 | F19: 2026-06-10 | G19: bigcommerce.com/essentials/pricing
B20: VTEX Business (anual R$ 60k) | C20: 5000 | D20: 5000 | E20: 5000 | F20: 2026-06-10 | G20: assine.vtex.com/vtex-commerce-suite-new-business
A22: B. PREÇOS DE SERVIÇOS — REFERÊNCIAS DE MERCADO BR
B23: Item | C23: Mínimo | D23: Médio | E23: Máximo | F23: Data | G23: Fonte / Observação
B24: Implementação e-commerce ENTRY (Nuvemshop/Tray template) | C24: 3000 | D24: 6000 | E24: 10000 | F24: 2026-06-10 | G24: mathcreator.com.br; safiradesign.com.br
B25: Implementação Shopify INTERMEDIÁRIO | C25: 8000 | D25: 18000 | E25: 25000 | F25: 2026-06-10 | G25: litextension.com/pt/blog/shopify-pricing; simplesinovacao.com
B26: Implementação Shopify/VTEX PREMIUM (custom) | C26: 25000 | D26: 35000 | E26: 60000 | F26: 2026-06-10 | G26: litextension.com
B27: Site institucional simples | C27: 3000 | D27: 5000 | E27: 6000 | F27: 2026-06-10 | G27: hostwp.com.br; safiradesign.com.br
B28: Site institucional premium | C28: 7000 | D28: 11000 | E28: 15000 | F28: 2026-06-10 | G28: hostwp.com.br; mathcreator.com.br
B29: Landing page básica (template) | C29: 300 | D29: 600 | E29: 900 | F29: 2026-06-10 | G29: gabrieldosite.com.br
B30: Landing page profissional | C30: 1200 | D30: 2500 | E30: 4000 | F30: 2026-06-10 | G30: bluepaper.io
B31: Landing page estratégica c/ funil/automação | C31: 2000 | D31: 4500 | E31: 8000 | F31: 2026-06-10 | G31: bluepaper.io
B32: Migração de plataforma (ex: VTEX→Shopify) | C32: 8000 | D32: 18000 | E32: 40000 | F32: 2026-06-10 | G32: hulkapps.com
B33: Integração ERP (Bling/Tiny/Omie) projeto único | C33: 490 | D33: 1500 | E33: 4000 | F33: 2026-06-10 | G33: brauerecommerce.com.br
B34: SEO técnico — auditoria pontual | C34: 1200 | D34: 4000 | E34: 8000 | F34: 2026-06-10 | G34: juanmoura.com; profissionalseo.com.br
B35: SEO técnico — mensal contínuo | C35: 2000 | D35: 5000 | E35: 15000 | F35: 2026-06-10 | G35: juanmoura.com
... B39: Squad agência (4-5 pessoas/mês) | C39: 60000 | D39: 90000 | E39: 120000 | F39: 2026-06-10 | G39: numerando.com.br
A41: C. PLANOS MENSAIS DE SUPORTE/MANUTENÇÃO BR
B42: Item | C42: Mínimo | D42: Médio | E42: Máximo | F42: Data | G42: Fonte / Observação
B43: WP Essencial 1 site, 2h, manutenção preventiva | C43: 199 | D43: 250 | E43: 300 | F43: 2026-06-10 | G43: profissionalwp.dev.br
B44: Loja virtual mid (6h, não cumulativas) | C44: 600 | D44: 900 | E44: 1200 | F44: 2026-06-10 | G44: linkwell.com.br — faixa estimada
B45: Mid-tier (10-20h, SLA 24h) | C45: 1500 | D45: 2500 | E45: 3500 | F45: 2026-06-10 | G45: ae.digital — estimativa
B46: Premium (30h+, SLA 4h úteis) | C46: 4000 | D46: 6000 | E46: 8000 | F46: 2026-06-10 | G46: found.pt — estimativa
...

Sheet 4. Custos Fixos
A1: CUSTOS FIXOS MENSAIS — CLASSIFICAÇÃO
B2: Classificação: 🟢 OBRIGATÓRIO (não pode faltar) | 🟡 RECOMENDADO | ⚪ OPCIONAL
B4: Item | C4: Valor R$ | D4: Classe | E4: Observação / Fonte
B5: Pró-labore sócio 1 | C5: ='2. Premissas'!C7 | D5: 🟢 OBRIGATÓRIO | E5: Art. 1.071 IV CC; mínimo p/ sustentar Fator R do Anexo III
B6: Pró-labore sócio 2 | C6: ='2. Premissas'!C7 | D6: 🟢 OBRIGATÓRIO | E6: Idem
B7: INSS sócios (11% sobre pró-labore total) | C7: ='2. Premissas'!C11 | D7: 🟢 OBRIGATÓRIO | E7: Art. 21 Lei 8.212/91 (até teto RGPS)
B8: Internet empresarial (fibra) | C8: 200 | D8: 🟢 OBRIGATÓRIO | E8: Vivo R$ 128,98; TIM R$ 119-159; média R$ 100-180
B9: Energia adicional home office | C9: 80 | D9: 🟢 OBRIGATÓRIO | E9: Enel SP R$ 0,91/kWh × ~45 kWh/sócio
B10: Google Workspace (2 usuários) | C10: 65 | D10: 🟢 OBRIGATÓRIO | E10: R$ 32,72/user × 2 (anual)
B11: Contabilidade especializada | C11: 800 | D11: 🟢 OBRIGATÓRIO | E11: ME especializada R$ 700-1.200; Contabilizei online R$ 195
B12: Certificado Digital A1 | C12: 20 | D12: 🟢 OBRIGATÓRIO | E12: R$ 220/ano; necessário p/ NFS-e
B13: Hospedagem site Impulso + domínio | C13: 50 | D13: 🟢 OBRIGATÓRIO | E13: Hostinger + Registro.br R$ 40/ano
B14: Antivírus + backup nuvem | C14: 80 | D14: 🟢 OBRIGATÓRIO | E14: Segurança da operação
B15: ChatGPT Plus + Claude Pro (IA) | C15: 220 | D15: 🟡 RECOMENDADO | E15: US$ 20 × 2 ≈ R$ 108 × 2
B16: Figma Professional (2 editores anual) | C16: 162 | D16: 🟡 RECOMENDADO | E16: US$ 15 × 2 ≈ R$ 81 × 2
B17: Seguro RC profissional (E&O) | C17: 150 | D17: 🟡 RECOMENDADO | E17: Recomendação jurídica — limita responsabilidade civil
B18: Marketing próprio (mídia + ferramentas) | C18: 1200 | D18: 🟡 RECOMENDADO | E18: R$ 3-5k ideal; piso R$ 1.200
B19: Make / Zapier (automação) | C19: 60 | D19: 🟡 RECOMENDADO | E19: Make Core US$ 10,59
... B26: Slack Pro (2 users) | C26: 78 | D26: ⚪ OPCIONAL | E26: WhatsApp+Google Chat substituem no início
B28: TOTAL OBRIGATÓRIO | C28: =SUMIF(D5:D26,"🟢 OBRIGATÓRIO",C5:C26)
B29: TOTAL RECOMENDADO | C29: =SUMIF(D5:D26,"🟡 RECOMENDADO",C5:C26)
B30: TOTAL OPCIONAL | C30: =SUMIF(D5:D26,"⚪ OPCIONAL",C5:C26)
B31: CUSTO MENSAL TOTAL (todos) | C31: =SUM(C5:C26)
B33: CUSTO TOTAL ANUAL | C33: =SUM(C5:C26)*12

Sheet 5. Custos Variáveis
A1: CUSTOS VARIÁVEIS (% sobre receita ou por projeto)
B2: Valores em % são aplicados sobre receita; valores em R$ são por projeto/cliente
B4: Item | C4: Valor / % | D4: Observação / Fonte
B5: (% sobre receita) Imposto Simples Anexo III | C5: ='2. Premissas'!C31 | D5: Premissa editável — efetivo real: 6% até R$ 180k/ano
B6: (% sobre receita) Taxa de cartão MÉDIA | C6: ='2. Premissas'!C69 | D6: Média ponderada das modalidades
B7: (% sobre receita) Inadimplência (PCLD) | C7: ='2. Premissas'!C38 | D7: Conservador: 4% serviços B2B BR
B8: (% sobre receita) Comissão indicação (parcerias) | C8: 0.1 | D8: 10-20% se houver indicador externo
B9: (R$ por projeto) Plugins/apps Shopify específicos | C9: 200 | D9: Quando o pacote inclui app pago (estimativa média)
B10: (R$ por projeto) Templates pagos / temas premium | C10: 300 | D10: Tema Shopify premium US$ 200-350
B11: (R$ por projeto) Banco de imagens / fontes | C11: 100 | D11: Adobe Stock, Freepik PRO, etc.
B12: (R$ por projeto) Subcontratado eventual (designer/copy freela) | C12: 800 | D12: Quando o escopo exigir — opcional
B13: (R$ por mês) Tráfego pago próprio (aquisição clientes) | C13: 1500 | D13: Repassado da aba 4 marketing; também variável
B14: (R$ por hora extra de atendimento pós-venda) | C14: 89 | D14: Custo de oportunidade da hora produtiva
B15: Provisão para cancelamentos/devoluções | C15: 1-3% da receita | D15: Recomendação contábil (CPC 25 — Provisões)

Sheet 6. Capacidade
A1: CAPACIDADE OPERACIONAL — análise de horas
A3: HORAS DISPONÍVEIS (por mês)
B4: Linha | C4: Por sócio | D4: Total (2 sócios) | E4: % das brutas | F4: Observação
B5: Horas BRUTAS (22 dias × 8h) | C5: ='2. Premissas'!C16 | D5: ='2. Premissas'!C17 | E5: 100% | F5: Linha de partida
B6: (-) Comercial (pré-venda, propostas, reuniões) | C6: ='2. Premissas'!C17*0.15/'2. Premissas'!C5 | D6: ='2. Premissas'!C17*0.15 | E6: 15% | F6: 53h totais
B7: (-) Atendimento ativo + briefing | C7: ='2. Premissas'!C17*0.10/'2. Premissas'!C5 | D7: ='2. Premissas'!C17*0.10 | E7: 10% | F7: 35h totais
B8: (-) Pós-venda + suporte/garantia | C8: ='2. Premissas'!C17*0.10/'2. Premissas'!C5 | D8: ='2. Premissas'!C17*0.10 | E8: 10% | F8: 35h totais
B9: (-) Admin + financeiro + reuniões internas | C9: ='2. Premissas'!C17*0.08/'2. Premissas'!C5 | D9: ='2. Premissas'!C17*0.08 | E9: 8% | F9: 28h totais
B10: (-) Gestão + estudo + atualização templates | C10: ='2. Premissas'!C17*0.07/'2. Premissas'!C5 | D10: ='2. Premissas'!C17*0.07 | E10: 7% | F10: 25h totais
B11: =HORAS PRODUTIVAS de execução pura | C11: ='2. Premissas'!C19/'2. Premissas'!C5 | D11: ='2. Premissas'!C19 | E11: 50% | F11: Padrão de planejamento: 176h
B12: Capacidade ALVO sustentável (≤80%) | C12: ='2. Premissas'!C22/'2. Premissas'!C5 | D12: ='2. Premissas'!C22 | E12: 40% | F12: Operar ≤80% evita burnout
A14: MIX MENSAL RECOMENDADO (alvo ≤80% de capacidade)
B15: Combinação | C15: Start (20h) | D15: Pro (40h) | E15: Premium (70h) | F15: Horas totais | G15: Avaliação
B16: Volume máximo (NÃO recomendado) | C16: 4 | D16: 1 | E16: 0 | F16: =C16*20+D16*40+E16*70 | G16: ❌ 200h — estoura (>80%)
B17: Volume saudável | C17: 3 | D17: 1 | E17: 0 | F17: =C17*20+D17*40+E17*70 | G17: ✅ 100h — ok com folga
B18: Equilibrado | C18: 2 | D18: 1 | E18: 0 | F18: =C18*20+D18*40+E18*70 | G18: ✅ 80h — confortável
B19: Premium-foco | C19: 1 | D19: 0 | E19: 1 | F19: =C19*20+D19*40+E19*70 | G19: ✅ 90h — sustentável
B20: Target sustentável (recomendado) | C20: 2 | D20: 1 | E20: 0 | F20: =C20*20+D20*40+E20*70 | G20: ✅ 80h — pode adicionar suporte
B21: Premium puro (a cada 2 meses) | C21: 0 | D21: 0 | E21: 1 | F21: =C21*20+D21*40+E21*70 | G21: ✅ 70h — ok mas baixo throughput
A23: LIMITES DE SUPORTE RECORRENTE POR SÓCIO
B24: Plano | C24: Horas/mês cliente | D24: Capacidade nominal/sócio | E24: Teto operacional/sócio | F24: Mix sustentável
B25: Essencial (4h/mês) | C25: 4 | D25: 45 | E25: 25 | F25: Combinar com 1-2 Pro
B26: Profissional (10h/mês) | C26: 10 | D26: 18 | E26: 12 | F26: Limite mais comum
B27: Growth (20h/mês) | C27: 20 | D27: 9 | E27: 6 | F27: Cliente premium
A29: GATILHOS PARA CONTRATAR O 3º PROFISSIONAL
B30: ☐ Backlog vendido > 200h por 2 meses consecutivos
B31: ☐ Capacidade alocada > 85% por 2 meses
B32: ☐ Recusa de ≥2 projetos qualificados por mês por falta de slot
B33: ☐ Suporte recorrente > 50h/mês combinado
B34: ☐ NPS cai abaixo de 8 ou atraso médio > 20% sobre prazo prometido
B35: ☐ MRR ≥ R$ 20.000 por 3 meses (cobre custo de contratação CLT-flex ~R$ 6-9k all-in)
B36: ☐ Sócios trabalhando > 55h/semana ou rejeitando projetos por capacidade
B37: ✅ Perfil ideal da 1ª contratação: IMPLEMENTADOR PLENO em Shopify/Tray (não sênior). R$ 5-7k CLT-flex ou PJ. Sócios sobem para vendas + suporte estratégico + conteúdo.

Sheet 7. Preço 48 Horas
A1: PRECIFICAÇÃO — PROJETO 48 HORAS (3 pacotes)
B2: Fórmula de precificação: PV = (CustoHora × Horas) ÷ (1 - %Imposto - %TaxaMédia - %Inadimplência - %Margem)
A4: ESCOPO POR PACOTE
B5: Item | C5: START | D5: PRO | E5: PREMIUM | F5: Observação
B6: Plataformas suportadas | C6: Shopify, Nuvemshop, WP | D6: Shopify, Nuvemshop, Tray | E6: Shopify, Tray | F6: Woo só com +30%
B7: Limite de SKUs | C7: 15 | D7: 50 | E7: 150 | F7: Cadastro com fotos prontas
B8: Limite de páginas | C8: 5 | D8: 8 | E8: 12 | F8: Páginas institucionais
B9: Limite de integrações | C9: 1 | D9: 1 | E9: 2 | F9: Bling OU Tiny OU RD
B10: Limite de gateways | C10: 1 | D10: 2 | E10: 2 | F10: Aprovado antes do start
B11: Limite de modalidades de frete | C11: 1 | D11: 2 | E11: 2 | F11: Melhor Envio/Correios
B12: Reuniões inclusas | C12: 3 | D12: 3 | E12: 5 | F12: Briefing + validação + treinamento
B13: Sessões de treinamento (60min) | C13: 1 | D13: 2 | E13: 2 | F13: + videoteca de acesso
B14: Dias de suporte pós-go-live | C14: 7 | D14: 15 | E14: 30 | F14: Após, plano mensal obrigatório
B15: Horas humanas estimadas (mín) | C15: 22 | D15: 45 | E15: 90 | F15: Cenário ideal com pré-condições
B16: Horas humanas estimadas (esperada) | C16: 32 | D16: 70 | E16: 130 | F16: Mediana operacional
B17: Horas humanas estimadas (máx) | C17: 45 | D17: 100 | E17: 180 | F17: Cenário stress
A19: PRECIFICAÇÃO CALCULADA (base: horas esperadas)
B20: Linha | C20: START | D20: PRO | E20: PREMIUM | F20: Fórmula / Origem
B21: Custo interno (R$) | C21: ='2. Premissas'!C68*C16 | D21: ='2. Premissas'!C68*D16 | E21: ='2. Premissas'!C68*E16 | F21: =custo/h × horas
B22: PREÇO MÍNIMO (margem 20%) | C22: =('2. Premissas'!C68*C16)/(1-'2. Premissas'!C31-'2. Premissas'!C69-'2. Premissas'!C38-'2. Premissas'!C26) | D22: =('2. Premissas'!C68*D16)/(1-'2. Premissas'!C31-'2. Premissas'!C69-'2. Premissas'!C38-'2. Premissas'!C26) | E22: =('2. Premissas'!C68*E16)/(1-'2. Premissas'!C31-'2. Premissas'!C69-'2. Premissas'!C38-'2. Premissas'!C26) | F22: Custo / (1 - 12% - tx méd - 4% - 20%)
B23: PREÇO RECOMENDADO (margem 40%) | C23: =('2. Premissas'!C68*C16)/(1-'2. Premissas'!C31-'2. Premissas'!C69-'2. Premissas'!C38-'2. Premissas'!C27) | D23: =('2. Premissas'!C68*D16)/(1-'2. Premissas'!C31-'2. Premissas'!C69-'2. Premissas'!C38-'2. Premissas'!C27) | E23: =('2. Premissas'!C68*E16)/(1-'2. Premissas'!C31-'2. Premissas'!C69-'2. Premissas'!C38-'2. Premissas'!C27) | F23: Custo / (1 - 12% - tx méd - 4% - 40%)
B24: PREÇO PREMIUM (margem 55%) | C24: =('2. Premissas'!C68*C16)/(1-'2. Premissas'!C31-'2. Premissas'!C69-'2. Premissas'!C38-'2. Premissas'!C28) | D24: =('2. Premissas'!C68*D16)/(1-'2. Premissas'!C31-'2. Premissas'!C69-'2. Premissas'!C38-'2. Premissas'!C28) | E24: =('2. Premissas'!C68*E16)/(1-'2. Premissas'!C31-'2. Premissas'!C69-'2. Premissas'!C38-'2. Premissas'!C28) | F24: Custo / (1 - 12% - tx méd - 4% - 55%)
B25: PREÇO COMERCIAL SUGERIDO (ancoragem) | C25: 2490 | D25: 4990 | E25: 8900 | F25: Recomendação CFO: ancoragem + colchão p/ desconto
B26: Margem líquida no preço sugerido | C26: =1-'2. Premissas'!C31-'2. Premissas'!C69-'2. Premissas'!C38-(('2. Premissas'!C68*C16)/C25) | D26: =1-'2. Premissas'!C31-'2. Premissas'!C69-'2. Premissas'!C38-(('2. Premissas'!C68*D16)/D25) | E26: =1-'2. Premissas'!C31-'2. Premissas'!C69-'2. Premissas'!C38-(('2. Premissas'!C68*E16)/E25) | F26: =1 - imp - tx - inad - custo%
A28: SIMULAÇÃO POR MODALIDADE DE PAGAMENTO — Pacote PRO (preço sugerido)
B29: Modalidade | C29: Valor bruto | D29: Taxa % | E29: Taxa R$ | F29: Imposto R$ | G29: Líquido recebido
B30: PIX | C30: =D25 | D30: ='2. Premissas'!C32 | E30: =D25*'2. Premissas'!C32 | F30: =D25*'2. Premissas'!C31 | G30: =C30-E30-F30
B31: Cartão à vista | C31: =D25 | D31: ='2. Premissas'!C33 | E31: =D25*'2. Premissas'!C33 | F31: =D25*'2. Premissas'!C31 | G31: =C31-E31-F31
B32: Cartão 3x | C32: =D25 | D32: ='2. Premissas'!C34 | E32: =D25*'2. Premissas'!C34 | F32: =D25*'2. Premissas'!C31 | G32: =C32-E32-F32
B33: Cartão 6x | C33: =D25 | D33: ='2. Premissas'!C35 | E33: =D25*'2. Premissas'!C35 | F33: =D25*'2. Premissas'!C31 | G33: =C33-E33-F33
B34: Cartão 10x | C34: =D25 | D34: ='2. Premissas'!C36 | E34: =D25*'2. Premissas'!C36 | F34: =D25*'2. Premissas'!C31 | G34: =C34-E34-F34
B35: Cartão 12x | C35: =D25 | D35: ='2. Premissas'!C37 | E35: =D25*'2. Premissas'!C37 | F35: =D25*'2. Premissas'!C31 | G35: =C35-E35-F35
B37: 💡 POLÍTICA RECOMENDADA: 5% off PIX/à vista; máx 3x sem juros; 6x+ com juros repassados ao cliente. DNS sob domínio Impulso até pagamento final (50/40/10).

Sheet 8. Personalizados
A1: PRECIFICAÇÃO — PROJETOS PERSONALIZADOS
B2: Mesma fórmula: PV = (CustoHora × Horas) ÷ (1 - %Imp - %Tx - %Inad - %Margem)
A4: TABELA DE PROJETOS PERSONALIZADOS
B5: Projeto | C5: Horas estim. | D5: Custo interno | E5: Imposto | F5: Taxa cartão | G5: Preço MÍNIMO (20%) | H5: Preço RECOMENDADO (40%) | I5: Preço PREMIUM (55%)
B6: Site institucional simples (até 5 páginas) | C6: 30 | D6: ='2. Premissas'!C68*C6 | E6: =G6*'2. Premissas'!C31 | F6: =G6*'2. Premissas'!C69 | G6: =D6/(1-'2. Premissas'!C31-'2. Premissas'!C69-'2. Premissas'!C38-'2. Premissas'!C26) | H6: =D6/(1-'2. Premissas'!C31-'2. Premissas'!C69-'2. Premissas'!C38-'2. Premissas'!C27) | I6: =D6/(1-'2. Premissas'!C31-'2. Premissas'!C69-'2. Premissas'!C38-'2. Premissas'!C28)
B7: Site institucional premium (até 10 páginas + funil) | C7: 60 | D7: ='2. Premissas'!C68*C7 | E7: =G7*'2. Premissas'!C31 | F7: =G7*'2. Premissas'!C69 | G7: =D7/(1-'2. Premissas'!C31-'2. Premissas'!C69-'2. Premissas'!C38-'2. Premissas'!C26) | H7: =D7/(1-'2. Premissas'!C31-'2. Premissas'!C69-'2. Premissas'!C38-'2. Premissas'!C27) | I7: =D7/(1-'2. Premissas'!C31-'2. Premissas'!C69-'2. Premissas'!C38-'2. Premissas'!C28)
B8: Loja virtual personalizada (50-100 SKUs + integrações) | C8: 100 | D8: ='2. Premissas'!C68*C8 | E8: =G8*'2. Premissas'!C31 | F8: =G8*'2. Premissas'!C69 | G8: =D8/(1-'2. Premissas'!C31-'2. Premissas'!C69-'2. Premissas'!C38-'2. Premissas'!C26) | H8: =D8/(1-'2. Premissas'!C31-'2. Premissas'!C69-'2. Premissas'!C38-'2. Premissas'!C27) | I8: =D8/(1-'2. Premissas'!C31-'2. Premissas'!C69-'2. Premissas'!C38-'2. Premissas'!C28)
B9: Migração de plataforma (ex.: VTEX → Shopify) | C9: 80 | D9: ='2. Premissas'!C68*C9 | E9: =G9*'2. Premissas'!C31 | F9: =G9*'2. Premissas'!C69 | G9: =D9/(1-'2. Premissas'!C31-'2. Premissas'!C69-'2. Premissas'!C38-'2. Premissas'!C26) | H9: =D9/(1-'2. Premissas'!C31-'2. Premissas'!C69-'2. Premissas'!C38-'2. Premissas'!C27) | I9: =D9/(1-'2. Premissas'!C31-'2. Premissas'!C69-'2. Premissas'!C38-'2. Premissas'!C28)
B10: Integração com ERP (Bling/Tiny/Omie) | C10: 25 | D10: ='2. Premissas'!C68*C10 | E10: =G10*'2. Premissas'!C31 | F10: =G10*'2. Premissas'!C69 | G10: =D10/(1-'2. Premissas'!C31-'2. Premissas'!C69-'2. Premissas'!C38-'2. Premissas'!C26) | H10: =D10/(1-'2. Premissas'!C31-'2. Premissas'!C69-'2. Premissas'!C38-'2. Premissas'!C27) | I10: =D10/(1-'2. Premissas'!C31-'2. Premissas'!C69-'2. Premissas'!C38-'2. Premissas'!C28)
B11: Integração marketplace (ML/Amazon) por canal | C11: 30 | D11: ='2. Premissas'!C68*C11 | E11: =G11*'2. Premissas'!C31 | F11: =G11*'2. Premissas'!C69 | G11: =D11/(1-'2. Premissas'!C31-'2. Premissas'!C69-'2. Premissas'!C38-'2. Premissas'!C26) | H11: =D11/(1-'2. Premissas'!C31-'2. Premissas'!C69-'2. Premissas'!C38-'2. Premissas'!C27) | I11: =D11/(1-'2. Premissas'!C31-'2. Premissas'!C69-'2. Premissas'!C38-'2. Premissas'!C28)
B12: SEO técnico — projeto completo | C12: 40 | D12: ='2. Premissas'!C68*C12 | E12: =G12*'2. Premissas'!C31 | F12: =G12*'2. Premissas'!C69 | G12: =D12/(1-'2. Premissas'!C31-'2. Premissas'!C69-'2. Premissas'!C38-'2. Premissas'!C26) | H12: =D12/(1-'2. Premissas'!C31-'2. Premissas'!C69-'2. Premissas'!C38-'2. Premissas'!C27) | I12: =D12/(1-'2. Premissas'!C31-'2. Premissas'!C69-'2. Premissas'!C38-'2. Premissas'!C28)
B13: Automação comercial (RD/HubSpot/Klaviyo) | C13: 30 | D13: ='2. Premissas'!C68*C13 | E13: =G13*'2. Premissas'!C31 | F13: =G13*'2. Premissas'!C69 | G13: =D13/(1-'2. Premissas'!C31-'2. Premissas'!C69-'2. Premissas'!C38-'2. Premissas'!C26) | H13: =D13/(1-'2. Premissas'!C31-'2. Premissas'!C69-'2. Premissas'!C38-'2. Premissas'!C27) | I13: =D13/(1-'2. Premissas'!C31-'2. Premissas'!C69-'2. Premissas'!C38-'2. Premissas'!C28)
B14: CRM — setup + treinamento | C14: 25 | D14: ='2. Premissas'!C68*C14 | E14: =G14*'2. Premissas'!C31 | F14: =G14*'2. Premissas'!C69 | G14: =D14/(1-'2. Premissas'!C31-'2. Premissas'!C69-'2. Premissas'!C38-'2. Premissas'!C26) | H14: =D14/(1-'2. Premissas'!C31-'2. Premissas'!C69-'2. Premissas'!C38-'2. Premissas'!C27) | I14: =D14/(1-'2. Premissas'!C31-'2. Premissas'!C69-'2. Premissas'!C38-'2. Premissas'!C28)
B15: Landing page profissional (com funil + automação) | C15: 20 | D15: ='2. Premissas'!C68*C15 | E15: =G15*'2. Premissas'!C31 | F15: =G15*'2. Premissas'!C69 | G15: =D15/(1-'2. Premissas'!C31-'2. Premissas'!C69-'2. Premissas'!C38-'2. Premissas'!C26) | H15: =D15/(1-'2. Premissas'!C31-'2. Premissas'!C69-'2. Premissas'!C38-'2. Premissas'!C27) | I15: =D15/(1-'2. Premissas'!C31-'2. Premissas'!C69-'2. Premissas'!C38-'2. Premissas'!C28)
B16: Auditoria de e-commerce completa | C16: 18 | D16: ='2. Premissas'!C68*C16 | E16: =G16*'2. Premissas'!C31 | F16: =G16*'2. Premissas'!C69 | G16: =D16/(1-'2. Premissas'!C31-'2. Premissas'!C69-'2. Premissas'!C38-'2. Premissas'!C26) | H16: =D16/(1-'2. Premissas'!C31-'2. Premissas'!C69-'2. Premissas'!C38-'2. Premissas'!C27) | I16: =D16/(1-'2. Premissas'!C31-'2. Premissas'!C69-'2. Premissas'!C38-'2. Premissas'!C28)
B17: Consultoria estratégica (mensal, 1 sócio sênior) | C17: 20 | D17: ='2. Premissas'!C68*C17 | E17: =G17*'2. Premissas'!C31 | F17: =G17*'2. Premissas'!C69 | G17: =D17/(1-'2. Premissas'!C31-'2. Premissas'!C69-'2. Premissas'!C38-'2. Premissas'!C26) | H17: =D17/(1-'2. Premissas'!C31-'2. Premissas'!C69-'2. Premissas'!C38-'2. Premissas'!C27) | I17: =D17/(1-'2. Premissas'!C31-'2. Premissas'!C69-'2. Premissas'!C38-'2. Premissas'!C28)
B19: 📌 Para projetos personalizados: SEMPRE escopo fechado por escrito + change request formal para qualquer item adicional. Política de revisões: 2 rodadas estéticas; excedentes faturados por hora.

Sheet 9. Suporte
A1: PLANOS MENSAIS DE SUPORTE E MANUTENÇÃO
A3: 3 PLANOS RECORRENTES (MRR)
B4: Item | C4: ESSENCIAL | D4: PROFISSIONAL | E4: GROWTH
B5: Horas inclusas por mês | C5: 4 | D5: 10 | E5: 20
B6: Valor mensal sugerido (R$) | C6: 397 | D6: 990 | E6: 1890
B7: Custo interno (R$) | C7: ='2. Premissas'!C68*C5 | D7: ='2. Premissas'!C68*D5 | E7: ='2. Premissas'!C68*E5
B8: Imposto Simples (R$) | C8: =C6*'2. Premissas'!C31 | D8: =D6*'2. Premissas'!C31 | E8: =E6*'2. Premissas'!C31
B9: Margem líquida estimada | C9: =1-'2. Premissas'!C31-'2. Premissas'!C69-'2. Premissas'!C38-C7/C6 | D9: =1-'2. Premissas'!C31-'2. Premissas'!C69-'2. Premissas'!C38-D7/D6 | E9: =1-'2. Premissas'!C31-'2. Premissas'!C69-'2. Premissas'!C38-E7/E6
B10: SLA resposta (h úteis) | C10: 24 | D10: 8 | E10: 4
B11: SLA resolução P1 | C11: 5 d.u. | D11: 24 h | E11: 8 h
B12: Vigência mínima sugerida | C12: 6 meses | D12: 12 meses | E12: 12 meses
B13: Reajuste anual | C13: IPCA | D13: IPCA | E13: IPCA
B14: Limite nominal por sócio | C14: 45 clientes | D14: 18 clientes | E14: 9 clientes
B15: Teto operacional sustentável/sócio | C15: 25-30 | D15: 12-15 | E15: 6-8
B16: Itens INCLUSOS | C16: Ajustes técnicos pontuais; atualização de banners; pequenas correções; monitoramento básico (uptime, backup); atendimento consultivo por mensagem | D16: Tudo do Essencial + alterações em página existente (até 3/mês); ajuste de tema sem código; relatório mensal simples; revisão mensal por sócio | E16: Tudo do Profissional + 1 sprint de melhoria/mês; otimização de conversão pontual; revisão de SEO mensal; reunião quinzenal de planejamento
B17: Itens NÃO INCLUSOS (orçamento à parte) | C17: Customização de código; nova página; nova integração; redesign; produção de conteúdo | D17: Customização de código; redesign; produção de conteúdo extenso; gestão de tráfego pago | E17: Redesign completo; novas integrações > 1; produção de conteúdo extenso; gestão de tráfego pago (vendido à parte)
A19: ESTRATÉGIA DE RECORRÊNCIA (squad strategy)
B20: Meta: 50% conversão setup → suporte mensal em 12 meses; 65% em 24 meses. Mecânicas: 1) Bundle de saída: setup já inclui 30 dias de suporte cortesia + oferta de mensalidade 20% off se contratada em 7 dias. 2) Revisão de resultados D+30 e D+60 com sócio → mostra dados → abre upsell para Profissional/Growth. 3) Comunidade Impulso acessível apenas a clientes em recorrência (status premium). 4) SLA visível no contrato. Cláusula de upgrade/downgrade com 30 dias de aviso prévio. 5) Vigência mínima 12 meses (Pro/Growth) — válida B2B; em B2C, atenção CDC art. 51 IV (multa rescisória proporcional). RECEITA RECORRENTE É O CORAÇÃO DO NEGÓCIO. 1 R$ MRR vale 3-5× 1 R$ de projeto.

Sheet 10. Parceria
A1: RECEITA RECORRENTE DE PARCERIAS COM PLATAFORMAS
B2: Comissão de indicação — natureza jurídica: intermediação (LC 116/03 itens 10.02 / 17.12)
A4: PARÂMETROS DAS PLATAFORMAS PARCEIRAS
B5: Plataforma | C5: Mensalidade média cliente (R$) | D5: % Comissão Impulso | E5: Receita/cliente/mês | F5: Fonte
B6: Shopify Basic (US$ 29-39) | C6: 180 | D6: 0.2 | E6: =C6*D6 | F6: help.shopify.com/partners
B7: Shopify Grow (US$ 79-105) | C7: 500 | D7: 0.2 | E7: =C7*D7 | F7: shopify.com/pricing
B8: Tray (R$ 49-99 médio) | C8: 75 | D8: 0.2 | E8: =C8*D8 | F8: tray.com.br/partners
B9: Nuvemshop Essencial | C9: 59 | D9: 0.2 | E9: =C9*D9 | F9: atendimento.nuvemshop.com.br — comissões vigentes
B10: Nuvemshop Impulso (homônimo) | C10: 139 | D10: 0.2 | E10: =C10*D10 | F10: nuvemshop.com.br/planos-e-precos
B11: Nuvemshop Escala | C11: 389 | D11: 0.2 | E11: =C11*D11 | F11: nuvemshop.com.br/planos-e-precos
A13: SIMULAÇÃO DE RECEITA RECORRENTE — 3 CENÁRIOS
B14: Cenário | C14: Clientes mês 3 | D14: mês 6 | E14: mês 12 | F14: mês 24 | G14: MRR mês 12 (R$) | H14: Anual ano 1 (R$)
B15: Pessimista | C15: 2 | D15: 4 | E15: 8 | F15: 15 | G15: =E15*60 | H15: =((C15+E15)/2)*12*60
B16: Realista | C16: 3 | D16: 8 | E16: 18 | F16: 35 | G16: =E16*60 | H16: =((C16+E16)/2)*12*60
B17: Otimista | C17: 5 | D17: 12 | E17: 30 | F17: 60 | G17: =E17*60 | H17: =((C17+E17)/2)*12*60
B19: ⚠️ Premissas do squad: (1) Receita média/cliente assumida R$ 60/mês — mix de planos Tray + Nuvemshop Essencial + Shopify Basic. (2) Churn 3-5% a.m. esperado — incorporado no ramping. (3) Receita Shopify Partners é EXPORTAÇÃO de serviço (ISS isento art. 2º I LC 116/03; tributação só CPP+IRPJ+CSLL no DAS — art. 18 §14 LC 123/06). (4) Contrato de câmbio obrigatório (Lei 14.286/21). (5) Não receber verba de mídia em conta — cliente paga direto a Meta/Google.

Sheet 11. Tráfego Pago
A1: GESTÃO DE TRÁFEGO PAGO — MODELOS DE COBRANÇA
B2: ⚠️ Cliente paga MÍDIA direto Meta/Google (NÃO transitar pela Impulso). Impulso cobra apenas FEE de gestão.
A4: MATRIZ DE PRECIFICAÇÃO POR FAIXA DE VERBA DO CLIENTE
B5: Faixa de verba do cliente | C5: Setup (R$) | D5: Fee mensal (R$) | E5: Horas/mês | F5: % sobre verba | G5: Custo interno (R$) | H5: Margem
B6: Até R$ 2.000/mês mídia | C6: 800 | D6: 1200 | E6: 8 | F6: 10-15% | G6: ='2. Premissas'!C68*E6 | H6: =1-G6/D6-'2. Premissas'!C31-'2. Premissas'!C69
B7: R$ 2-5k mídia | C7: 1500 | D7: 2250 | E7: 12 | F7: 12-15% | G7: ='2. Premissas'!C68*E7 | H7: =1-G7/D7-'2. Premissas'!C31-'2. Premissas'!C69
B8: R$ 5-10k mídia | C8: 2500 | D8: 3750 | E8: 18 | F8: 10-15% | G8: ='2. Premissas'!C68*E8 | H8: =1-G8/D8-'2. Premissas'!C31-'2. Premissas'!C69
B9: >R$ 10k mídia | C9: 3500 | D9: 5000 | E9: 25 | F9: 10-12% | G9: ='2. Premissas'!C68*E9 | H9: =1-G9/D9-'2. Premissas'!C31-'2. Premissas'!C69
A11: MODELOS DE COBRANÇA — VANTAGENS E RISCOS
B12: Modelo | C12: Vantagens | D12: Riscos | E12: Quando usar
B13: Setup + Fee fixo mensal | C13: Previsibilidade total; alinhado a serviço, não a verba | D13: Cliente pode reduzir verba e exigir mesmo fee | E13: Recomendado p/ clientes pequenos
B14: % sobre verba (10-20%) | C14: Cresce com cliente; alinhado a investimento | D14: Variação do faturamento; risco se cliente cortar verba | E14: Cliente médio/grande
B15: Pacote híbrido (fee + %) | C15: Equilíbrio entre previsibilidade e upside | D15: Mais complexo de explicar | E15: MELHOR para clientes em escala
B16: Consultoria avulsa (hora) | C16: Margem alta em projetos pontuais | D16: Não escala; sem recorrência | E16: Auditorias + workshops
B18: ⚠️ Cláusula contratual obrigatória: 'A Impulso não garante volume, ROAS, CPA, faturamento ou ROI; tais resultados dependem de fatores externos (mercado, produto, preço, sazonalidade, política das plataformas).' (CDC art. 39 IV)

Sheet 12. Cenários
A1: CENÁRIOS FINANCEIROS — PROJEÇÃO 12 MESES
A4: CENÁRIO PESSIMISTA
B5: Linha | C5: M1 | D5: M2 | E5: M3 | F5: M4 | G5: M5 | H5: M6 | I5: M7 | J5: M8 | K5: M9 | L5: M10 | M5: M11 | N5: M12 | O5: Caixa final | P5: TOTAL ANO
B6: Receita Projeto 48h | C6: 3240 | D6: 3240 | E6: 3240 | F6: 6480 | G6: 6480 | H6: 6480 | I6: 6480 | J6: 9720 | K6: 9720 | L6: 9720 | M6: 9720 | N6: 9720 | P6: =SUM(C6:N6)
B7: Receita Personalizados | C7: 0 | D7: 0 | E7: 0 | F7: 0 | G7: 0 | H7: 0 | I7: 0 | J7: 0 | K7: 0 | L7: 0 | M7: 0 | N7: 0 | P7: 0
B8: Receita Suporte Mensal (acumulado) | C8: 0 | D8: 397 | E8: 794 | F8: 794 | G8: 1191 | H8: 1588 | I8: 1985 | J8: 2382 | K8: 2779 | L8: 3176 | M8: 3573 | N8: 3970 | P8: =SUM(C8:N8)
B9: Receita Parceria (acumulado) | C9: 0 | D9: 0 | E9: 0 | F9: 0 | G9: 0 | H9: 0 | I9: 60 | J9: 120 | K9: 180 | L9: 300 | M9: 420 | N9: 540 | P9: =SUM(C9:N9)
B10: Receita Tráfego Pago | C10: 0 | D10: 0 | E10: 0 | F10: 0 | G10: 0 | H10: 0 | I10: 0 | J10: 0 | K10: 0 | L10: 0 | M10: 0 | N10: 0 | P10: =SUM(C10:N10)
B11: RECEITA BRUTA TOTAL | C11: =SUM(C6:C10) | D11: =SUM(D6:D10) | E11: =SUM(E6:E10) | F11: =SUM(F6:F10) | G11: =SUM(G6:G10) | H11: =SUM(H6:H10) | I11: =SUM(I6:I10) | J11: =SUM(J6:J10) | ... N11: =SUM(N6:N10) | P11: =SUM(C11:N11)
B12: (-) Impostos (Simples 12%) | C12: =C11*'2. Premissas'!C31 | D12: =D11*'2. Premissas'!C31 | E12: =E11*'2. Premissas'!C31 | F12: =F11*'2. Premissas'!C31 | G12: =G11*'2. Premissas'!C31 | H12: =H11*'2. Premissas'!C31 | I12: =I11*'2. Premissas'!C31 | J12: =J11*'2. Premissas'!C31 | K12: =K11*'2. Premissas'!C31 | L12: =L11*'2. Premissas'!C31 | M12: =M11*'2. Premissas'!C31 | N12: =N11*'2. Premissas'!C31 | P12: =SUM(C12:N12)
B13: (-) Taxas cartão (média) | C13: =C11*'2. Premissas'!C69 | D13: =D11*'2. Premissas'!C69 | E13: =E11*'2. Premissas'!C69 | F13: =F11*'2. Premissas'!C69 | G13: =G11*'2. Premissas'!C69 | H13: =H11*'2. Premissas'!C69 | I13: =I11*'2. Premissas'!C69 | J13: =J11*'2. Premissas'!C69 | K13: =K11*'2. Premissas'!C69 | L13: =L11*'2. Premissas'!C69 | M13: =M11*'2. Premissas'!C69 | N13: =N11*'2. Premissas'!C69 | P13: =SUM(C13:N13)
B14: (-) Inadimplência (PCLD) | C14: =C11*'2. Premissas'!C38 | D14: =D11*'2. Premissas'!C38 | E14: =E11*'2. Premissas'!C38 | F14: =F11*'2. Premissas'!C38 | G14: =G11*'2. Premissas'!C38 | H14: =H11*'2. Premissas'!C38 | I14: =I11*'2. Premissas'!C38 | J14: =J11*'2. Premissas'!C38 | K14: =K11*'2. Premissas'!C38 | L14: =L11*'2. Premissas'!C38 | M14: =M11*'2. Premissas'!C38 | N14: =N11*'2. Premissas'!C38 | P14: =SUM(C14:N14)
B15: (-) Custos Fixos (sem pró-labore) | C15: ='2. Premissas'!C62 | D15: ='2. Premissas'!C62 | E15: ='2. Premissas'!C62 | F15: ='2. Premissas'!C62 | G15: ='2. Premissas'!C62 | H15: ='2. Premissas'!C62 | I15: ='2. Premissas'!C62 | J15: ='2. Premissas'!C62 | K15: ='2. Premissas'!C62 | L15: ='2. Premissas'!C62 | M15: ='2. Premissas'!C62 | N15: ='2. Premissas'!C62 | P15: =SUM(C15:N15)
B16: (-) Pró-labore + INSS sócios | C16: ='2. Premissas'!C9+'2. Premissas'!C11 | D16: ='2. Premissas'!C9+'2. Premissas'!C11 | E16: ='2. Premissas'!C9+'2. Premissas'!C11 | F16: ='2. Premissas'!C9+'2. Premissas'!C11 | G16: ='2. Premissas'!C9+'2. Premissas'!C11 | H16: ='2. Premissas'!C9+'2. Premissas'!C11 | I16: ='2. Premissas'!C9+'2. Premissas'!C11 | J16: ='2. Premissas'!C9+'2. Premissas'!C11 | K16: ='2. Premissas'!C9+'2. Premissas'!C11 | L16: ='2. Premissas'!C9+'2. Premissas'!C11 | M16: ='2. Premissas'!C9+'2. Premissas'!C11 | N16: ='2. Premissas'!C9+'2. Premissas'!C11 | P16: =SUM(C16:N16)
B17: LUCRO MENSAL | C17: =C11-C12-C13-C14-C15-C16 | D17: =D11-D12-D13-D14-D15-D16 | E17: =E11-E12-E13-E14-E15-E16 | F17: =F11-F12-F13-F14-F15-F16 | G17: =G11-G12-G13-G14-G15-G16 | H17: =H11-H12-H13-H14-H15-H16 | I17: =I11-I12-I13-I14-I15-I16 | J17: =J11-J12-J13-J14-J15-J16 | ... N17: =N11-N12-N13-N14-N15-N16 | P17: =SUM(C17:N17)
B18: Margem líquida % | C18: =IFERROR(C17/C11,0) | D18: =IFERROR(D17/D11,0) | E18: =IFERROR(E17/E11,0) | F18: =IFERROR(F17/F11,0) | G18: =IFERROR(G17/G11,0) | H18: =IFERROR(H17/H11,0) | I18: =IFERROR(I17/I11,0) | J18: =IFERROR(J17/J11,0) | ... N18: =IFERROR(N17/N11,0) | P18: =IFERROR(P17/P11,0)
B19: Caixa acumulado | C19: =C17 | D19: =C19+D17 | E19: =D19+E17 | F19: =E19+F17 | G19: =F19+G17 | H19: =G19+H17 | I19: =H19+I17 | J19: =I19+J17 | K19: =J19+K17 | ... N19: =M19+N17 | O19: =N19
B22: RESUMO ANUAL DO CENÁRIO
A31: CENÁRIO REALISTA
B32: Linha | C32: M1 | D32: M2 | E32: M3 | F32: M4 | G32: M5 | H32: M6 | I32: M7 | J32: M8 | K32: M9 | L32: M10 | M32: M11 | N32: M12 | O32: Caixa final | P32: TOTAL ANO
B33: Receita Projeto 48h | C33: 9544 | D33: 9544 | E33: 14316 | F33: 14316 | G33: 14316 | H33: 14316 | I33: 14316 | J33: 14316 | K33: 14316 | L33: 14316 | M33: 14316 | N33: 14316 | P33: =SUM(C33:N33)
B34: Receita Personalizados | C34: 0 | D34: 0 | E34: 0 | F34: 0 | G34: 0 | H34: 0 | I34: 0 | J34: 0 | K34: 0 | L34: 0 | M34: 0 | N34: 0 | P34: 0
B35: Receita Suporte Mensal (acumulado) | C35: 990 | D35: 2970 | E35: 4950 | F35: 6930 | G35: 8910 | H35: 10890 | I35: 12870 | J35: 14850 | K35: 16830 | L35: 18810 | M35: 20790 | N35: 22770 | P35: =SUM(C35:N35)
B36: Receita Parceria (acumulado) | C36: 0 | D36: 0 | E36: 60 | F36: 120 | G36: 240 | H36: 360 | I36: 480 | J36: 600 | K36: 720 | L36: 840 | M36: 960 | N36: 1080 | P36: =SUM(C36:N36)
B37: Receita Tráfego Pago | C37: 0 | D37: 0 | E37: 0 | F37: 2500 | G37: 2500 | H37: 2500 | I37: 2500 | J37: 2500 | K37: 2500 | L37: 2500 | M37: 2500 | N37: 2500 | P37: =SUM(C37:N37)
B38: RECEITA BRUTA TOTAL | C38: =SUM(C33:C37) | D38: =SUM(D33:D37) | E38: =SUM(E33:E37) | F38: =SUM(F33:F37) | G38: =SUM(G33:G37) | H38: =SUM(H33:H37) | I38: =SUM(I33:I37) | J38: =SUM(J33:J37) | ... N38: =SUM(N33:N37) | P38: =SUM(C38:N38)
B39: (-) Impostos (Simples 12%) | C39: =C38*'2. Premissas'!C31 | D39: =D38*'2. Premissas'!C31 | E39: =E38*'2. Premissas'!C31 | F39: =F38*'2. Premissas'!C31 | G39: =G38*'2. Premissas'!C31 | H39: =H38*'2. Premissas'!C31 | I39: =I38*'2. Premissas'!C31 | J39: =J38*'2. Premissas'!C31 | K39: =K38*'2. Premissas'!C31 | L39: =L38*'2. Premissas'!C31 | M39: =M38*'2. Premissas'!C31 | N39: =N38*'2. Premissas'!C31 | P39: =SUM(C39:N39)
B40: (-) Taxas cartão (média) | C40: =C38*'2. Premissas'!C69 | D40: =D38*'2. Premissas'!C69 | E40: =E38*'2. Premissas'!C69 | F40: =F38*'2. Premissas'!C69 | G40: =G38*'2. Premissas'!C69 | H40: =H38*'2. Premissas'!C69 | I40: =I38*'2. Premissas'!C69 | J40: =J38*'2. Premissas'!C69 | K40: =K38*'2. Premissas'!C69 | L40: =L38*'2. Premissas'!C69 | M40: =M38*'2. Premissas'!C69 | N40: =N38*'2. Premissas'!C69 | P40: =SUM(C40:N40)
B41: (-) Inadimplência (PCLD) | C41: =C38*'2. Premissas'!C38 | D41: =D38*'2. Premissas'!C38 | E41: =E38*'2. Premissas'!C38 | F41: =F38*'2. Premissas'!C38 | G41: =G38*'2. Premissas'!C38 | H41: =H38*'2. Premissas'!C38 | I41: =I38*'2. Premissas'!C38 | J41: =J38*'2. Premissas'!C38 | K41: =K38*'2. Premissas'!C38 | L41: =L38*'2. Premissas'!C38 | M41: =M38*'2. Premissas'!C38 | N41: =N38*'2. Premissas'!C38 | P41: =SUM(C41:N41)
B42: (-) Custos Fixos (sem pró-labore) | C42: ='2. Premissas'!C62 | D42: ='2. Premissas'!C62 | E42: ='2. Premissas'!C62 | F42: ='2. Premissas'!C62 | G42: ='2. Premissas'!C62 | H42: ='2. Premissas'!C62 | I42: ='2. Premissas'!C62 | J42: ='2. Premissas'!C62 | K42: ='2. Premissas'!C62 | L42: ='2. Premissas'!C62 | M42: ='2. Premissas'!C62 | N42: ='2. Premissas'!C62 | P42: =SUM(C42:N42)
B43: (-) Pró-labore + INSS sócios | C43: ='2. Premissas'!C9+'2. Premissas'!C11 | D43: ='2. Premissas'!C9+'2. Premissas'!C11 | E43: ='2. Premissas'!C9+'2. Premissas'!C11 | F43: ='2. Premissas'!C9+'2. Premissas'!C11 | G43: ='2. Premissas'!C9+'2. Premissas'!C11 | H43: ='2. Premissas'!C9+'2. Premissas'!C11 | I43: ='2. Premissas'!C9+'2. Premissas'!C11 | J43: ='2. Premissas'!C9+'2. Premissas'!C11 | K43: ='2. Premissas'!C9+'2. Premissas'!C11 | L43: ='2. Premissas'!C9+'2. Premissas'!C11 | M43: ='2. Premissas'!C9+'2. Premissas'!C11 | N43: ='2. Premissas'!C9+'2. Premissas'!C11 | P43: =SUM(C43:N43)
B44: LUCRO MENSAL | C44: =C38-C39-C40-C41-C42-C43 | D44: =D38-D39-D40-D41-D42-D43 | E44: =E38-E39-E40-E41-E42-E43 | F44: =F38-F39-F40-F41-F42-F43 | G44: =G38-G39-G40-G41-G42-G43 | H44: =H38-H39-H40-H41-H42-H43 | I44: =I38-I39-I40-I41-I42-I43 | J44: =J38-J39-J40-J41-J42-J43 | ... N44: =N38-N39-N40-N41-N42-N43 | P44: =SUM(C44:N44)
B45: Margem líquida % | C45: =IFERROR(C44/C38,0) | D45: =IFERROR(D44/D38,0) | E45: =IFERROR(E44/E38,0) | F45: =IFERROR(F44/F38,0) | G45: =IFERROR(G44/G38,0) | H45: =IFERROR(H44/H38,0) | I45: =IFERROR(I44/I38,0) | J45: =IFERROR(J44/J38,0) | ... N45: =IFERROR(N44/N38,0) | P45: =IFERROR(P44/P38,0)
B46: Caixa acumulado | C46: =C44 | D46: =C46+D44 | E46: =D46+E44 | F46: =E46+F44 | G46: =F46+G44 | H46: =G46+H44 | I46: =H46+I44 | J46: =I46+J44 | K46: =J46+K44 | ... N46: =M46+N44 | O46: =N46
B49: RESUMO ANUAL DO CENÁRIO
A58: CENÁRIO OTIMISTA
B59: Linha | C59: M1 | D59: M2 | E59: M3 | F59: M4 | G59: M5 | H59: M6 | I59: M7 | J59: M8 | K59: M9 | L59: M10 | M59: M11 | N59: M12 | O59: Caixa final | P59: TOTAL ANO
B60: Receita Projeto 48h | C60: 15066 | D60: 20088 | E60: 20088 | F60: 25110 | G60: 25110 | H60: 25110 | I60: 25110 | J60: 25110 | K60: 25110 | L60: 25110 | M60: 25110 | N60: 25110 | P60: =SUM(C60:N60)
B61: Receita Personalizados | C61: 0 | D61: 0 | E61: 0 | F61: 0 | G61: 0 | H61: 0 | I61: 0 | J61: 0 | K61: 0 | L61: 0 | M61: 0 | N61: 0 | P61: 0
B62: Receita Suporte Mensal (acumulado) | C62: 1980 | D62: 4950 | E62: 7920 | F62: 10890 | G62: 13860 | H62: 16830 | I62: 19800 | J62: 22770 | K62: 25740 | L62: 28710 | M62: 31680 | N62: 34650 | P62: =SUM(C62:N62)
...

Sheet 13. DRE
A1: DRE PROJETADA — CENÁRIO REALISTA (12 meses)
B2: Estrutura conforme CPC 26 (R1). Vinculada à aba 12 — Realista (linhas 31-48)
B4: Linha DRE | C4: M1 | D4: M2 | E4: M3 | F4: M4 | G4: M5 | H4: M6 | I4: M7 | J4: M8 | K4: M9 | L4: M10 | M4: M11 | N4: M12 | O4: ANO
B5: RECEITA BRUTA OPERACIONAL | C5: ='12. Cenários'!C38 | D5: ='12. Cenários'!D38 | E5: ='12. Cenários'!E38 | F5: ='12. Cenários'!F38 | G5: ='12. Cenários'!G38 | H5: ='12. Cenários'!H38 | I5: ='12. Cenários'!I38 | J5: ='12. Cenários'!J38 | ... N5: ='12. Cenários'!N38 | O5: ='12. Cenários'!P38
B6: Projeto 48 Horas | C6: ='12. Cenários'!C33 | D6: ='12. Cenários'!D33 | E6: ='12. Cenários'!E33 | F6: ='12. Cenários'!F33 | G6: ='12. Cenários'!G33 | H6: ='12. Cenários'!H33 | I6: ='12. Cenários'!I33 | J6: ='12. Cenários'!J33 | ... N6: ='12. Cenários'!N33 | O6: ='12. Cenários'!P33
B7: Projetos Personalizados | C7: ='12. Cenários'!C34 | D7: ='12. Cenários'!D34 | E7: ='12. Cenários'!E34 | F7: ='12. Cenários'!F34 | G7: ='12. Cenários'!G34 | H7: ='12. Cenários'!H34 | I7: ='12. Cenários'!I34 | J7: ='12. Cenários'!J34 | ... N7: ='12. Cenários'!N34 | O7: ='12. Cenários'!P34
B8: Suporte Mensal Recorrente (MRR) | C8: ='12. Cenários'!C35 | D8: ='12. Cenários'!D35 | E8: ='12. Cenários'!E35 | F8: ='12. Cenários'!F35 | G8: ='12. Cenários'!G35 | H8: ='12. Cenários'!H35 | I8: ='12. Cenários'!I35 | J8: ='12. Cenários'!J35 | ... N8: ='12. Cenários'!N35 | O8: ='12. Cenários'!P35
B9: Parceria com Plataformas | C9: ='12. Cenários'!C36 | D9: ='12. Cenários'!D36 | E9: ='12. Cenários'!E36 | F9: ='12. Cenários'!F36 | G9: ='12. Cenários'!G36 | H9: ='12. Cenários'!H36 | I9: ='12. Cenários'!I36 | J9: ='12. Cenários'!J36 | ... N9: ='12. Cenários'!N36 | O9: ='12. Cenários'!P36
B10: Tráfego Pago (gestão) | C10: ='12. Cenários'!C37 | D10: ='12. Cenários'!D37 | E10: ='12. Cenários'!E37 | F10: ='12. Cenários'!F37 | G10: ='12. Cenários'!G37 | H10: ='12. Cenários'!H37 | I10: ='12. Cenários'!I37 | J10: ='12. Cenários'!J37 | ... N10: ='12. Cenários'!N37 | O10: ='12. Cenários'!P37
B11: (–) Impostos sobre venda (Simples) | C11: ='12. Cenários'!C39 | D11: ='12. Cenários'!D39 | E11: ='12. Cenários'!E39 | F11: ='12. Cenários'!F39 | G11: ='12. Cenários'!G39 | H11: ='12. Cenários'!H39 | I11: ='12. Cenários'!I39 | J11: ='12. Cenários'!J39 | ... N11: ='12. Cenários'!N39 | O11: ='12. Cenários'!P39
B12: (–) Taxas de cartão | C12: ='12. Cenários'!C40 | D12: ='12. Cenários'!D40 | E12: ='12. Cenários'!E40 | F12: ='12. Cenários'!F40 | G12: ='12. Cenários'!G40 | H12: ='12. Cenários'!H40 | I12: ='12. Cenários'!I40 | J12: ='12. Cenários'!J40 | ... N12: ='12. Cenários'!N40 | O12: ='12. Cenários'!P40
B13: (–) Inadimplência (PCLD) | C13: ='12. Cenários'!C41 | D13: ='12. Cenários'!D41 | E13: ='12. Cenários'!E41 | F13: ='12. Cenários'!F41 | G13: ='12. Cenários'!G41 | H13: ='12. Cenários'!H41 | I13: ='12. Cenários'!I41 | J13: ='12. Cenários'!J41 | ... N13: ='12. Cenários'!N41 | O13: ='12. Cenários'!P41
B14: =RECEITA LÍQUIDA | C14: ='12. Cenários'!C38 - '12. Cenários'!C39 - '12. Cenários'!C40 - '12. Cenários'!C41 | D14: ='12. Cenários'!D38 - '12. Cenários'!D39 - '12. Cenários'!D40 - '12. Cenários'!D41 | E14: ='12. Cenários'!E38 - '12. Cenários'!E39 - '12. Cenários'!E40 - '12. Cenários'!E41 | F14: ='12. Cenários'!F38 - '12. Cenários'!F39 - '12. Cenários'!F40 - '12. Cenários'!F41 | G14: ='12. Cenários'!G38 - '12. Cenários'!G39 - '12. Cenários'!G40 - '12. Cenários'!G41 | H14: ='12. Cenários'!H38 - '12. Cenários'!H39 - '12. Cenários'!H40 - '12. Cenários'!H41 | I14: ='12. Cenários'!I38 - '12. Cenários'!I39 - '12. Cenários'!I40 - '12. Cenários'!I41 | J14: ='12. Cenários'!J38 - '12. Cenários'!J39 - '12. Cenários'!J40 - '12. Cenários'!J41 | ... N14: ='12. Cenários'!N38 - '12. Cenários'!N39 - '12. Cenários'!N40 - '12. Cenários'!N41 | O14: ='12. Cenários'!P38 - '12. Cenários'!P39 - '12. Cenários'!P40 - '12. Cenários'!P41
B15: (–) Custos Fixos Administrativos | C15: ='12. Cenários'!C42 | D15: ='12. Cenários'!D42 | E15: ='12. Cenários'!E42 | F15: ='12. Cenários'!F42 | G15: ='12. Cenários'!G42 | H15: ='12. Cenários'!H42 | I15: ='12. Cenários'!I42 | J15: ='12. Cenários'!J42 | ... N15: ='12. Cenários'!N42 | O15: ='12. Cenários'!P42
B16: (–) Pró-labore + INSS sócios | C16: ='12. Cenários'!C43 | D16: ='12. Cenários'!D43 | E16: ='12. Cenários'!E43 | F16: ='12. Cenários'!F43 | G16: ='12. Cenários'!G43 | H16: ='12. Cenários'!H43 | I16: ='12. Cenários'!I43 | J16: ='12. Cenários'!J43 | ... N16: ='12. Cenários'!N43 | O16: ='12. Cenários'!P43
B17: =LUCRO LÍQUIDO MENSAL | C17: ='12. Cenários'!C44 | D17: ='12. Cenários'!D44 | E17: ='12. Cenários'!E44 | F17: ='12. Cenários'!F44 | G17: ='12. Cenários'!G44 | H17: ='12. Cenários'!H44 | I17: ='12. Cenários'!I44 | J17: ='12. Cenários'!J44 | ... N17: ='12. Cenários'!N44 | O17: ='12. Cenários'!P44
B18: Margem líquida (%) | C18: =IFERROR('12. Cenários'!C44/'12. Cenários'!C38,0) | D18: =IFERROR('12. Cenários'!D44/'12. Cenários'!D38,0) | E18: =IFERROR('12. Cenários'!E44/'12. Cenários'!E38,0) | F18: =IFERROR('12. Cenários'!F44/'12. Cenários'!F38,0) | G18: =IFERROR('12. Cenários'!G44/'12. Cenários'!G38,0) | H18: =IFERROR('12. Cenários'!H44/'12. Cenários'!H38,0) | I18: =IFERROR('12. Cenários'!I44/'12. Cenários'!I38,0) | J18: =IFERROR('12. Cenários'!J44/'12. Cenários'!J38,0) | ... N18: =IFERROR('12. Cenários'!N44/'12. Cenários'!N38,0) | O18: =IFERROR('12. Cenários'!P44/'12. Cenários'!P38,0)

Sheet 14. Fluxo de Caixa
A1: FLUXO DE CAIXA — CENÁRIO REALISTA (12 meses)
B2: Considera descasamento entre receita reconhecida e caixa efetivamente recebido (parcelamento)
B4: Movimento | C4: M1 | D4: M2 | E4: M3 | F4: M4 | G4: M5 | H4: M6 | I4: M7 | J4: M8 | K4: M9 | L4: M10 | M4: M11 | N4: M12 | O4: ANO
B5: (+) Recebimentos à vista/PIX (60% da receita) | C5: ='12. Cenários'!C38*0.6 | D5: ='12. Cenários'!D38*0.6 | E5: ='12. Cenários'!E38*0.6 | F5: ='12. Cenários'!F38*0.6 | G5: ='12. Cenários'!G38*0.6 | H5: ='12. Cenários'!H38*0.6 | I5: ='12. Cenários'!I38*0.6 | J5: ='12. Cenários'!J38*0.6 | ... N5: ='12. Cenários'!N38*0.6 | O5: =SUM(C5:N5)
B6: (+) Recebimentos parcelado 3x (30% receita, diluído em 3 meses) | C6: ='12. Cenários'!C38*0.3 | D6: ='12. Cenários'!D38*0.3 | E6: ='12. Cenários'!E38*0.3 | F6: ='12. Cenários'!F38*0.3 | G6: ='12. Cenários'!G38*0.3 | H6: ='12. Cenários'!H38*0.3 | I6: ='12. Cenários'!I38*0.3 | J6: ='12. Cenários'!J38*0.3 | ... N6: ='12. Cenários'!N38*0.3 | O6: =SUM(C6:N6)
B7: (+) Recebimentos parcelado 6x+ (10% receita) | C7: ='12. Cenários'!C38*0.1 | D7: ='12. Cenários'!D38*0.1 | E7: ='12. Cenários'!E38*0.1 | F7: ='12. Cenários'!F38*0.1 | G7: ='12. Cenários'!G38*0.1 | H7: ='12. Cenários'!H38*0.1 | I7: ='12. Cenários'!I38*0.1 | J7: ='12. Cenários'!J38*0.1 | ... N7: ='12. Cenários'!N38*0.1 | O7: =SUM(C7:N7)
B8: =TOTAL ENTRADAS | C8: =SUM(C5:C7) | D8: =SUM(D5:D7) | E8: =SUM(E5:E7) | F8: =SUM(F5:F7) | G8: =SUM(G5:G7) | H8: =SUM(H5:H7) | I8: =SUM(I5:I7) | J8: =SUM(J5:J7) | ... N8: =SUM(N5:N7) | O8: =SUM(C8:N8)
B10: (–) Impostos (Simples) | C10: ='12. Cenários'!C39 | D10: ='12. Cenários'!D39 | E10: ='12. Cenários'!E39 | F10: ='12. Cenários'!F39 | G10: ='12. Cenários'!G39 | H10: ='12. Cenários'!H39 | I10: ='12. Cenários'!I39 | J10: ='12. Cenários'!J39 | ... N10: ='12. Cenários'!N39 | O10: =SUM(C10:N10)
B11: (–) Taxas cartão | C11: ='12. Cenários'!C40 | D11: ='12. Cenários'!D40 | E11: ='12. Cenários'!E40 | F11: ='12. Cenários'!F40 | G11: ='12. Cenários'!G40 | H11: ='12. Cenários'!H40 | I11: ='12. Cenários'!I40 | J11: ='12. Cenários'!J40 | ... N11: ='12. Cenários'!N40 | O11: =SUM(C11:N11)
B12: (–) Inadimplência (PCLD) | C12: ='12. Cenários'!C41 | D12: ='12. Cenários'!D41 | E12: ='12. Cenários'!E41 | F12: ='12. Cenários'!F41 | G12: ='12. Cenários'!G41 | H12: ='12. Cenários'!H41 | I12: ='12. Cenários'!I41 | J12: ='12. Cenários'!J41 | ... N12: ='12. Cenários'!N41 | O12: =SUM(C12:N12)
B13: (–) Custos fixos administrativos | C13: ='2. Premissas'!C62 | D13: ='2. Premissas'!C62 | E13: ='2. Premissas'!C62 | F13: ='2. Premissas'!C62 | G13: ='2. Premissas'!C62 | H13: ='2. Premissas'!C62 | I13: ='2. Premissas'!C62 | J13: ='2. Premissas'!C62 | K13: ='2. Premissas'!C62 | L13: ='2. Premissas'!C62 | M13: ='2. Premissas'!C62 | N13: ='2. Premissas'!C62 | O13: =SUM(C13:N13)
B14: (–) Pró-labore + INSS sócios | C14: ='2. Premissas'!C9+'2. Premissas'!C11 | D14: ='2. Premissas'!C9+'2. Premissas'!C11 | E14: ='2. Premissas'!C9+'2. Premissas'!C11 | F14: ='2. Premissas'!C9+'2. Premissas'!C11 | G14: ='2. Premissas'!C9+'2. Premissas'!C11 | H14: ='2. Premissas'!C9+'2. Premissas'!C11 | I14: ='2. Premissas'!C9+'2. Premissas'!C11 | J14: ='2. Premissas'!C9+'2. Premissas'!C11 | K14: ='2. Premissas'!C9+'2. Premissas'!C11 | L14: ='2. Premissas'!C9+'2. Premissas'!C11 | M14: ='2. Premissas'!C9+'2. Premissas'!C11 | N14: ='2. Premissas'!C9+'2. Premissas'!C11 | O14: =SUM(C14:N14)
B15: =TOTAL SAÍDAS | C15: =C10+C11+C12+C13+C14 | D15: =D10+D11+D12+D13+D14 | E15: =E10+E11+E12+E13+E14 | F15: =F10+F11+F12+F13+F14 | G15: =G10+G11+G12+G13+G14 | H15: =H10+H11+H12+H13+H14 | I15: =I10+I11+I12+I13+I14 | J15: =J10+J11+J12+J13+J14 | ... N15: =N10+N11+N12+N13+N14 | O15: =SUM(C15:N15)
B17: =FLUXO DE CAIXA DO MÊS | C17: =C8-C15 | D17: =D8-D15 | E17: =E8-E15 | F17: =F8-F15 | G17: =G8-G15 | H17: =H8-H15 | I17: =I8-I15 | J17: =J8-J15 | ... N17: =N8-N15 | O17: =SUM(C17:N17)
B18: (+) Caixa inicial (reserva) | C18: 50000 | D18: =C19 | E18: =D19 | F18: =E19 | G18: =F19 | H18: =G19 | I18: =H19 | J18: =I19 | K18: =J19 | ... N18: =M19
B19: =CAIXA FINAL ACUMULADO | C19: =C18+C17 | D19: =D18+D17 | E19: =E18+E17 | F19: =F18+F17 | G19: =G18+G17 | H19: =H18+H17 | I19: =I18+I17 | J19: =J18+J17 | ... N19: =N18+N17 | O19: =N19
B21: ⚠️ Premissa de fluxo: 60% PIX/à vista | 30% em até 3x | 10% em 6x+. Modelo simplificado — não considera antecipação de recebíveis. Capital de giro inicial: R$ 50.000 (recomendação CFO; ajustar em B41 se mudar). Risco do parcelado: descasamento receita reconhecida vs caixa pode chegar a 60-90 dias.

Sheet 15. Ponto Equilíbrio
A1: PONTO DE EQUILÍBRIO — FATURAMENTO MÍNIMO MENSAL
A3: FÓRMULA E CÁLCULO
B4: Componente | C4: Valor | D4: Origem
B5: Custo fixo total mensal (com pró-labore + INSS) | C5: ='2. Premissas'!C63 | D5: Soma da aba 2 — premissas
B6: Imposto Simples | C6: ='2. Premissas'!C31 | D6: Premissa editável
B7: Taxa cartão média | C7: ='2. Premissas'!C69 | D7: Média ponderada
B8: Inadimplência | C8: ='2. Premissas'!C38 | D8: PCLD 4%
B9: Deduções variáveis totais (impostos + taxa + inad) | C9: ='2. Premissas'!C70 | D9: Soma das 3 deduções
B10: Margem de contribuição efetiva | C10: =1-'2. Premissas'!C70 | D10: =1 - deduções
B12: 🎯 PONTO DE EQUILÍBRIO MENSAL (R$) | C12: ='2. Premissas'!C63/(1-'2. Premissas'!C70) | D12: PE = CF / (1 - deduções variáveis)
B13: Ponto de equilíbrio ANUAL | C13: =C12*12
B14: Margem de segurança recomendada (+30%) | C14: =C12*1.3 | D14: Patamar saudável de operação
A16: COMBINAÇÕES PARA ATINGIR O PE (exemplos)
B17: Combinação | C17: Receita projetada | D17: Atinge PE?
B18: 4 projetos Pro/mês (R$ 4.990 × 4) | C18: =4990*4 | D18: =IF(C18>=$C$12,"✅ Sim","❌ Não")
B19: 3 Start + 1 Pro/mês | C19: =2490*3+4990 | D19: =IF(C19>=$C$12,"✅ Sim","❌ Não")
B20: 2 Pro + 1 Premium | C20: =4990*2+8900 | D20: =IF(C20>=$C$12,"✅ Sim","❌ Não")
B21: 10 contratos Suporte Pro (MRR) | C21: =990*10 | D21: =IF(C21>=$C$12,"✅ Sim","❌ Não")
B22: 8 contratos Suporte Pro + 1 Start | C22: =990*8+2490 | D22: =IF(C22>=$C$12,"✅ Sim","❌ Não")
B23: 2 Start + 1 Pro + 5 Suporte Pro (MIX REALISTA) | C23: =2490*2+4990+990*5 | D23: =IF(C23>=$C$12,"✅ Sim","❌ Não")
B24: 1 Premium + 8 Suporte Pro | C24: =8900+990*8 | D24: =IF(C24>=$C$12,"✅ Sim","❌ Não")
B26: 💡 PE em horas faturáveis: dividir o PE pela hora de venda recomendada (R$ 89-118/h) — equivale a ~140-180h/mês. Isso representa 40-50% da capacidade produtiva total. Operar a partir de R$ 25.000/mês oferece margem de segurança confortável.

Sheet 16. Indicadores
A1: INDICADORES ESTRATÉGICOS (KPIs)
B2: Dashboard de acompanhamento mensal — use as fórmulas como referência
A4: INDICADORES OPERACIONAIS E FINANCEIROS
B5: Indicador | C5: Fórmula | D5: Meta | E5: Como medir / Observação
B6: Ticket médio Projeto 48h | C6: Receita 48h / qtd projetos | D6: R$ 4.500-5.500 | E6: Mix Start/Pro/Premium influencia
B7: MRR (Monthly Recurring Revenue) | C7: Soma das mensalidades ativas no mês | D7: R$ 25.000 até mês 12 | E7: Coração do negócio — KR principal do OKR2
B8: ARR (Annual Recurring Revenue) | C8: MRR × 12 | D8: R$ 300.000 até mês 12 | E8: Para avaliação do negócio
B9: CAC (Custo de Aquisição de Cliente) | C9: Marketing total / clientes novos | D9: < R$ 800 | E9: Payback < 3 meses
B10: LTV (Lifetime Value) | C10: Ticket × meses de retenção × margem | D10: > R$ 5.000 | E10: LTV/CAC ratio > 5
B11: Churn mensal | C11: Cancelamentos / base ativa | D11: < 4% | E11: Crítico para MRR sustentável
B12: Conversão Projeto → Suporte mensal | C12: Clientes em suporte / clientes total | D12: 60% em 12m | 65% em 24m | E12: Mecânicas: bundle, revisão D+30/D+60
